Thread-6 | attempted access to fixture Session from outside a request
Thread-6 | attempted access to fixture Session from outside a request
Thread-10 | attempted access to fixture Session from outside a request
Thread-10 | attempted access to fixture Session from outside a request
Thread-7 | Traceback (most recent call last):
  File "C:\Users\mikau\Desktop\Homework\SPRING23\CSE183\py4web\py4web\core.py", line 938, in wrapper
    ret = func(*func_args, **func_kwargs)
  File "C:\Users\mikau\Desktop\Homework\SPRING23\CSE183\py4web\py4web\core.py", line 923, in wrapper
    raise context["exception"]
  File "C:\Users\mikau\Desktop\Homework\SPRING23\CSE183\py4web\py4web\core.py", line 902, in wrapper
    context["output"] = func(*args, **kwargs)
  File "C:\Users\mikau\Desktop\Homework\SPRING23\CSE183\183-Group-Project\apps\planner\controllers.py", line 57, in get_users
    users = db(q).select(db.auth_user.ALL).as_list()
NameError: name 'q' is not defined

